{
    DataVersion: 3465,
    size: [10, 26, 15],
    data: [
        {pos: [3, 0, 8], state: "minecraft:stone"},
        {pos: [2, 1, 8], state: "minecraft:vine{east:true,north:false,south:false,up:false,west:false}"},
        {pos: [3, 1, 8], state: "create:zinc_ore"},
        {pos: [4, 1, 8], state: "minecraft:stone"},
        {pos: [2, 2, 7], state: "minecraft:vine{east:true,north:false,south:false,up:false,west:false}"},
        {pos: [2, 2, 8], state: "minecraft:vine{east:true,north:false,south:false,up:false,west:false}"},
        {pos: [3, 2, 8], state: "minecraft:gravel"},
        {pos: [4, 2, 7], state: "minecraft:stone"},
        {pos: [4, 2, 8], state: "minecraft:stone"},
        {pos: [7, 2, 7], state: "minecraft:vine{east:false,north:false,south:false,up:false,west:true}"},
        {pos: [2, 3, 7], state: "minecraft:vine{east:true,north:false,south:false,up:false,west:false}"},
        {pos: [2, 3, 8], state: "minecraft:vine{east:true,north:false,south:false,up:false,west:false}"},
        {pos: [3, 3, 7], state: "minecraft:iron_ore"},
        {pos: [3, 3, 8], state: "minecraft:gravel"},
        {pos: [3, 3, 9], state: "minecraft:vine{east:false,north:true,south:false,up:false,west:false}"},
        {pos: [4, 3, 6], state: "minecraft:stone"},
        {pos: [4, 3, 7], state: "minecraft:coal_ore"},
        {pos: [4, 3, 8], state: "minecraft:stone"},
        {pos: [7, 3, 7], state: "minecraft:vine{east:false,north:false,south:false,up:false,west:true}"},
        {pos: [2, 4, 5], state: "minecraft:vine{east:false,north:false,south:true,up:false,west:false}"},
        {pos: [2, 4, 8], state: "minecraft:vine{east:true,north:false,south:false,up:false,west:false}"},
        {pos: [3, 4, 6], state: "minecraft:iron_ore"},
        {pos: [3, 4, 7], state: "minecraft:andesite"},
        {pos: [3, 4, 8], state: "minecraft:stone"},
        {pos: [3, 4, 9], state: "minecraft:vine{east:false,north:true,south:false,up:false,west:false}"},
        {pos: [4, 4, 6], state: "minecraft:andesite"},
        {pos: [4, 4, 7], state: "minecraft:stone"},
        {pos: [4, 4, 8], state: "minecraft:iron_ore"},
        {pos: [5, 4, 7], state: "minecraft:cobweb"},
        {pos: [7, 4, 7], state: "minecraft:vine{east:false,north:false,south:false,up:false,west:true}"},
        {pos: [1, 5, 6], state: "minecraft:vine{east:false,north:false,south:true,up:false,west:false}"},
        {pos: [1, 5, 8], state: "minecraft:pointed_dripstone{thickness:tip,vertical_direction:down,waterlogged:false}"},
        {pos: [2, 5, 5], state: "minecraft:vine{east:false,north:false,south:true,up:false,west:false}"},
        {pos: [2, 5, 7], state: "minecraft:diorite"},
        {pos: [2, 5, 8], state: "minecraft:vine{east:true,north:true,south:false,up:true,west:false}"},
        {pos: [3, 5, 6], state: "minecraft:andesite"},
        {pos: [3, 5, 7], state: "minecraft:andesite"},
        {pos: [3, 5, 8], state: "create:zinc_ore"},
        {pos: [4, 5, 5], state: "minecraft:stone"},
        {pos: [4, 5, 6], state: "minecraft:stone"},
        {pos: [4, 5, 7], state: "minecraft:lava{level:0}"},
        {pos: [4, 5, 8], state: "minecraft:iron_ore"},
        {pos: [4, 5, 9], state: "minecraft:cobweb"},
        {pos: [5, 5, 6], state: "minecraft:cobweb"},
        {pos: [5, 5, 7], state: "minecraft:coal_ore"},
        {pos: [7, 5, 7], state: "minecraft:vine{east:false,north:false,south:false,up:false,west:true}"},
        {pos: [1, 6, 6], state: "minecraft:vine{east:false,north:false,south:true,up:false,west:false}"},
        {pos: [1, 6, 7], state: "minecraft:vine{east:false,north:false,south:false,up:true,west:false}"},
        {pos: [1, 6, 8], state: "minecraft:pointed_dripstone{thickness:frustum,vertical_direction:down,waterlogged:false}"},
        {pos: [2, 6, 5], state: "minecraft:vine{east:false,north:false,south:true,up:true,west:false}"},
        {pos: [2, 6, 6], state: "minecraft:andesite"},
        {pos: [2, 6, 7], state: "minecraft:diorite"},
        {pos: [2, 6, 8], state: "minecraft:stone"},
        {pos: [3, 6, 5], state: "minecraft:diorite"},
        {pos: [3, 6, 6], state: "minecraft:andesite"},
        {pos: [3, 6, 7], state: "create:zinc_ore"},
        {pos: [3, 6, 8], state: "minecraft:andesite"},
        {pos: [3, 6, 9], state: "minecraft:pointed_dripstone{thickness:tip,vertical_direction:down,waterlogged:false}"},
        {pos: [4, 6, 5], state: "minecraft:stone"},
        {pos: [4, 6, 6], state: "minecraft:stone"},
        {pos: [4, 6, 7], state: "minecraft:andesite"},
        {pos: [4, 6, 8], state: "minecraft:gravel"},
        {pos: [4, 6, 9], state: "minecraft:diorite"},
        {pos: [5, 6, 6], state: "minecraft:stone"},
        {pos: [5, 6, 7], state: "minecraft:gravel"},
        {pos: [5, 6, 8], state: "minecraft:dirt"},
        {pos: [7, 6, 7], state: "minecraft:vine{east:false,north:false,south:false,up:false,west:true}"},
        {pos: [0, 7, 7], state: "minecraft:vine{east:true,north:false,south:false,up:false,west:false}"},
        {pos: [1, 7, 6], state: "minecraft:vine{east:false,north:false,south:true,up:false,west:false}"},
        {pos: [1, 7, 7], state: "minecraft:diorite"},
        {pos: [1, 7, 8], state: "minecraft:dripstone_block"},
        {pos: [1, 7, 9], state: "minecraft:pointed_dripstone{thickness:tip,vertical_direction:down,waterlogged:false}"},
        {pos: [2, 7, 5], state: "minecraft:clay"},
        {pos: [2, 7, 6], state: "minecraft:gravel"},
        {pos: [2, 7, 7], state: "minecraft:iron_ore"},
        {pos: [2, 7, 8], state: "minecraft:stone"},
        {pos: [2, 7, 9], state: "minecraft:pointed_dripstone{thickness:tip,vertical_direction:down,waterlogged:false}"},
        {pos: [3, 7, 5], state: "minecraft:diorite"},
        {pos: [3, 7, 6], state: "create:zinc_ore"},
        {pos: [3, 7, 7], state: "minecraft:iron_ore"},
        {pos: [3, 7, 8], state: "minecraft:andesite"},
        {pos: [3, 7, 9], state: "minecraft:dripstone_block"},
        {pos: [3, 7, 10], state: "minecraft:pointed_dripstone{thickness:tip,vertical_direction:down,waterlogged:false}"},
        {pos: [4, 7, 5], state: "minecraft:stone"},
        {pos: [4, 7, 6], state: "minecraft:stone"},
        {pos: [4, 7, 7], state: "minecraft:coal_ore"},
        {pos: [4, 7, 8], state: "minecraft:diorite"},
        {pos: [4, 7, 9], state: "minecraft:diorite"},
        {pos: [5, 7, 5], state: "minecraft:iron_ore"},
        {pos: [5, 7, 6], state: "minecraft:dirt"},
        {pos: [5, 7, 7], state: "minecraft:diorite"},
        {pos: [5, 7, 8], state: "minecraft:diorite"},
        {pos: [5, 7, 9], state: "minecraft:cobweb"},
        {pos: [6, 7, 6], state: "minecraft:dirt"},
        {pos: [6, 7, 7], state: "minecraft:dirt"},
        {pos: [6, 7, 8], state: "minecraft:dirt"},
        {pos: [6, 7, 9], state: "minecraft:vine{east:false,north:true,south:false,up:false,west:false}"},
        {pos: [7, 7, 7], state: "minecraft:vine{east:false,north:false,south:false,up:true,west:true}"},
        {pos: [7, 7, 8], state: "minecraft:vine{east:false,north:false,south:false,up:true,west:true}"},
        {pos: [0, 8, 7], state: "minecraft:vine{east:true,north:false,south:true,up:false,west:false}"},
        {pos: [1, 8, 6], state: "minecraft:vine{east:false,north:false,south:true,up:true,west:false}"},
        {pos: [1, 8, 7], state: "minecraft:diorite"},
        {pos: [1, 8, 8], state: "minecraft:water{level:0}"},
        {pos: [1, 8, 9], state: "minecraft:dripstone_block"},
        {pos: [2, 8, 4], state: "minecraft:cobweb"},
        {pos: [2, 8, 5], state: "minecraft:clay"},
        {pos: [2, 8, 6], state: "minecraft:gravel"},
        {pos: [2, 8, 7], state: "minecraft:stone"},
        {pos: [2, 8, 8], state: "minecraft:stone"},
        {pos: [2, 8, 9], state: "minecraft:dripstone_block"},
        {pos: [3, 8, 4], state: "minecraft:dirt"},
        {pos: [3, 8, 5], state: "minecraft:clay"},
        {pos: [3, 8, 6], state: "minecraft:diorite"},
        {pos: [3, 8, 7], state: "minecraft:dirt"},
        {pos: [3, 8, 8], state: "minecraft:stone"},
        {pos: [3, 8, 9], state: "minecraft:lava{level:0}"},
        {pos: [3, 8, 10], state: "minecraft:dripstone_block"},
        {pos: [4, 8, 5], state: "minecraft:sand"},
        {pos: [4, 8, 6], state: "minecraft:dirt"},
        {pos: [4, 8, 7], state: "minecraft:stone"},
        {pos: [4, 8, 8], state: "minecraft:iron_ore"},
        {pos: [4, 8, 9], state: "minecraft:diorite"},
        {pos: [4, 8, 10], state: "minecraft:diorite"},
        {pos: [5, 8, 5], state: "minecraft:dirt"},
        {pos: [5, 8, 6], state: "minecraft:dirt"},
        {pos: [5, 8, 7], state: "minecraft:iron_ore"},
        {pos: [5, 8, 8], state: "minecraft:gravel"},
        {pos: [5, 8, 9], state: "minecraft:diorite"},
        {pos: [6, 8, 5], state: "minecraft:dirt"},
        {pos: [6, 8, 6], state: "minecraft:dirt"},
        {pos: [6, 8, 7], state: "minecraft:dirt"},
        {pos: [6, 8, 8], state: "minecraft:dirt"},
        {pos: [7, 8, 6], state: "minecraft:cobweb"},
        {pos: [7, 8, 7], state: "minecraft:dirt"},
        {pos: [7, 8, 8], state: "minecraft:dirt"},
        {pos: [8, 8, 7], state: "minecraft:dirt"},
        {pos: [0, 9, 6], state: "minecraft:vine{east:true,north:false,south:false,up:false,west:false}"},
        {pos: [0, 9, 7], state: "minecraft:vine{east:true,north:false,south:true,up:true,west:false}"},
        {pos: [0, 9, 8], state: "minecraft:dirt"},
        {pos: [1, 9, 5], state: "minecraft:vine{east:false,north:false,south:true,up:false,west:false}"},
        {pos: [1, 9, 6], state: "create:zinc_ore"},
        {pos: [1, 9, 7], state: "minecraft:diorite"},
        {pos: [1, 9, 8], state: "minecraft:stone"},
        {pos: [1, 9, 9], state: "minecraft:diorite"},
        {pos: [2, 9, 4], state: "minecraft:grass_block{snowy:false}"},
        {pos: [2, 9, 5], state: "minecraft:dirt"},
        {pos: [2, 9, 6], state: "minecraft:stone"},
        {pos: [2, 9, 7], state: "minecraft:iron_ore"},
        {pos: [2, 9, 8], state: "minecraft:diorite"},
        {pos: [2, 9, 9], state: "minecraft:diorite"},
        {pos: [3, 9, 4], state: "minecraft:dirt"},
        {pos: [3, 9, 5], state: "minecraft:dirt"},
        {pos: [3, 9, 6], state: "minecraft:iron_ore"},
        {pos: [3, 9, 7], state: "minecraft:dirt"},
        {pos: [3, 9, 8], state: "minecraft:diorite"},
        {pos: [3, 9, 9], state: "minecraft:dripstone_block"},
        {pos: [3, 9, 10], state: "minecraft:diorite"},
        {pos: [3, 9, 11], state: "minecraft:cobweb"},
        {pos: [4, 9, 4], state: "minecraft:dirt"},
        {pos: [4, 9, 5], state: "minecraft:sand"},
        {pos: [4, 9, 6], state: "minecraft:sand"},
        {pos: [4, 9, 7], state: "minecraft:clay"},
        {pos: [4, 9, 8], state: "minecraft:diorite"},
        {pos: [4, 9, 9], state: "minecraft:dirt"},
        {pos: [4, 9, 10], state: "minecraft:dirt"},
        {pos: [5, 9, 4], state: "minecraft:dirt"},
        {pos: [5, 9, 5], state: "minecraft:dirt"},
        {pos: [5, 9, 6], state: "minecraft:dirt"},
        {pos: [5, 9, 7], state: "minecraft:gravel"},
        {pos: [5, 9, 9], state: "minecraft:dirt"},
        {pos: [6, 9, 4], state: "minecraft:grass_block{snowy:false}"},
        {pos: [6, 9, 5], state: "minecraft:grass_block{snowy:false}"},
        {pos: [6, 9, 6], state: "minecraft:dirt"},
        {pos: [6, 9, 7], state: "minecraft:dirt"},
        {pos: [6, 9, 8], state: "minecraft:dirt"},
        {pos: [6, 9, 9], state: "minecraft:grass_block{snowy:false}"},
        {pos: [7, 9, 4], state: "minecraft:grass_block{snowy:false}"},
        {pos: [7, 9, 5], state: "minecraft:grass_block{snowy:false}"},
        {pos: [7, 9, 6], state: "minecraft:dirt"},
        {pos: [7, 9, 7], state: "minecraft:dirt"},
        {pos: [7, 9, 8], state: "minecraft:dirt"},
        {pos: [7, 9, 9], state: "minecraft:grass_block{snowy:false}"},
        {pos: [8, 9, 5], state: "minecraft:grass_block{snowy:false}"},
        {pos: [8, 9, 6], state: "minecraft:grass_block{snowy:false}"},
        {pos: [8, 9, 7], state: "minecraft:dirt"},
        {pos: [8, 9, 8], state: "minecraft:grass_block{snowy:false}"},
        {pos: [8, 9, 9], state: "minecraft:grass_block{snowy:false}"},
        {pos: [9, 9, 6], state: "minecraft:grass_block{snowy:false}"},
        {pos: [9, 9, 7], state: "minecraft:grass_block{snowy:false}"},
        {pos: [9, 9, 8], state: "minecraft:grass_block{snowy:false}"},
        {pos: [0, 10, 6], state: "minecraft:cobweb"},
        {pos: [0, 10, 7], state: "minecraft:dirt"},
        {pos: [0, 10, 8], state: "minecraft:dirt"},
        {pos: [1, 10, 6], state: "minecraft:dirt"},
        {pos: [1, 10, 7], state: "minecraft:dirt"},
        {pos: [1, 10, 8], state: "minecraft:stone"},
        {pos: [1, 10, 9], state: "minecraft:iron_ore"},
        {pos: [1, 10, 10], state: "minecraft:stone"},
        {pos: [2, 10, 4], state: "minecraft:tall_grass{half:lower}"},
        {pos: [2, 10, 5], state: "minecraft:grass_block{snowy:false}"},
        {pos: [2, 10, 6], state: "minecraft:dirt"},
        {pos: [2, 10, 7], state: "minecraft:grass_block{snowy:false}"},
        {pos: [2, 10, 8], state: "minecraft:grass_block{snowy:false}"},
        {pos: [2, 10, 9], state: "minecraft:dirt"},
        {pos: [2, 10, 10], state: "minecraft:diorite"},
        {pos: [2, 10, 11], state: "minecraft:dirt"},
        {pos: [3, 10, 4], state: "minecraft:grass_block{snowy:false}"},
        {pos: [3, 10, 5], state: "minecraft:grass_block{snowy:false}"},
        {pos: [3, 10, 6], state: "minecraft:grass_block{snowy:false}"},
        {pos: [3, 10, 7], state: "minecraft:farmland{moisture:7}"},
        {pos: [3, 10, 8], state: "minecraft:grass_block{snowy:false}"},
        {pos: [3, 10, 9], state: "minecraft:grass_block{snowy:false}"},
        {pos: [3, 10, 10], state: "minecraft:dirt"},
        {pos: [3, 10, 11], state: "minecraft:grass_block{snowy:false}"},
        {pos: [4, 10, 3], state: "minecraft:grass_block{snowy:false}"},
        {pos: [4, 10, 4], state: "minecraft:grass_block{snowy:false}"},
        {pos: [4, 10, 5], state: "minecraft:grass_block{snowy:false}"},
        {pos: [4, 10, 6], state: "minecraft:farmland{moisture:7}"},
        {pos: [4, 10, 7], state: "minecraft:water{level:0}"},
        {pos: [4, 10, 8], state: "minecraft:farmland{moisture:7}"},
        {pos: [4, 10, 9], state: "minecraft:grass_block{snowy:false}"},
        {pos: [4, 10, 10], state: "minecraft:grass_block{snowy:false}"},
        {pos: [5, 10, 4], state: "minecraft:grass_block{snowy:false}"},
        {pos: [5, 10, 5], state: "minecraft:grass_block{snowy:false}"},
        {pos: [5, 10, 6], state: "minecraft:grass_block{snowy:false}"},
        {pos: [5, 10, 7], state: "minecraft:farmland{moisture:7}"},
        {pos: [5, 10, 8], state: "minecraft:grass_block{snowy:false}"},
        {pos: [5, 10, 9], state: "minecraft:grass_block{snowy:false}"},
        {pos: [6, 10, 4], state: "minecraft:grass"},
        {pos: [6, 10, 5], state: "minecraft:grass"},
        {pos: [6, 10, 6], state: "minecraft:grass_block{snowy:false}"},
        {pos: [6, 10, 7], state: "minecraft:dirt"},
        {pos: [6, 10, 8], state: "minecraft:grass_block{snowy:false}"},
        {pos: [7, 10, 4], state: "minecraft:grass"},
        {pos: [7, 10, 5], state: "minecraft:grass"},
        {pos: [7, 10, 6], state: "minecraft:grass_block{snowy:false}"},
        {pos: [7, 10, 7], state: "minecraft:grass_block{snowy:false}"},
        {pos: [7, 10, 8], state: "minecraft:grass_block{snowy:false}"},
        {pos: [7, 10, 9], state: "minecraft:tall_grass{half:lower}"},
        {pos: [8, 10, 5], state: "minecraft:tall_grass{half:lower}"},
        {pos: [8, 10, 7], state: "minecraft:grass_block{snowy:false}"},
        {pos: [8, 10, 8], state: "minecraft:tall_grass{half:lower}"},
        {pos: [8, 10, 9], state: "minecraft:grass"},
        {pos: [9, 10, 6], state: "minecraft:tall_grass{half:lower}"},
        {pos: [9, 10, 8], state: "minecraft:grass"},
        {pos: [0, 11, 6], state: "minecraft:cobweb"},
        {pos: [0, 11, 7], state: "minecraft:grass_block{snowy:false}"},
        {pos: [0, 11, 8], state: "minecraft:dirt"},
        {pos: [0, 11, 9], state: "minecraft:dirt"},
        {pos: [1, 11, 6], state: "minecraft:dirt"},
        {pos: [1, 11, 7], state: "minecraft:grass_block{snowy:false}"},
        {pos: [1, 11, 8], state: "minecraft:grass_block{snowy:false}"},
        {pos: [1, 11, 9], state: "minecraft:iron_ore"},
        {pos: [1, 11, 10], state: "minecraft:dirt"},
        {pos: [2, 11, 4], state: "minecraft:tall_grass{half:upper}"},
        {pos: [2, 11, 6], state: "minecraft:grass_block{snowy:false}"},
        {pos: [2, 11, 7], state: "minecraft:torch"},
        {pos: [2, 11, 8], state: "minecraft:poppy"},
        {pos: [2, 11, 9], state: "minecraft:grass_block{snowy:false}"},
        {pos: [2, 11, 10], state: "minecraft:grass_block{snowy:false}"},
        {pos: [2, 11, 11], state: "minecraft:dirt"},
        {pos: [3, 11, 4], state: "minecraft:tall_grass{half:lower}"},
        {pos: [3, 11, 5], state: "minecraft:tall_grass{half:lower}"},
        {pos: [3, 11, 7], state: "minecraft:potatoes{age:7}"},
        {pos: [3, 11, 8], state: "minecraft:grass"},
        {pos: [3, 11, 9], state: "minecraft:tall_grass{half:lower}"},
        {pos: [3, 11, 10], state: "minecraft:grass_block{snowy:false}"},
        {pos: [3, 11, 11], state: "minecraft:tall_grass{half:lower}"},
        {pos: [4, 11, 4], state: "minecraft:grass"},
        {pos: [4, 11, 5], state: "minecraft:tall_grass{half:lower}"},
        {pos: [4, 11, 6], state: "minecraft:potatoes{age:7}"},
        {pos: [4, 11, 8], state: "minecraft:potatoes{age:7}"},
        {pos: [4, 11, 10], state: "minecraft:grass"},
        {pos: [5, 11, 5], state: "minecraft:tall_grass{half:lower}"},
        {pos: [5, 11, 6], state: "minecraft:grass"},
        {pos: [5, 11, 7], state: "minecraft:potatoes{age:7}"},
        {pos: [5, 11, 8], state: "minecraft:grass"},
        {pos: [5, 11, 9], state: "minecraft:dandelion"},
        {pos: [6, 11, 6], state: "minecraft:grass"},
        {pos: [6, 11, 7], state: "minecraft:oak_log{axis:y}"},
        {pos: [6, 11, 8], state: "minecraft:tall_grass{half:lower}"},
        {pos: [7, 11, 6], state: "minecraft:tall_grass{half:lower}"},
        {pos: [7, 11, 7], state: "minecraft:grass"},
        {pos: [7, 11, 8], state: "minecraft:grass"},
        {pos: [7, 11, 9], state: "minecraft:tall_grass{half:upper}"},
        {pos: [8, 11, 5], state: "minecraft:tall_grass{half:upper}"},
        {pos: [8, 11, 8], state: "minecraft:tall_grass{half:upper}"},
        {pos: [9, 11, 6], state: "minecraft:tall_grass{half:upper}"},
        {pos: [0, 12, 6], state: "minecraft:grass_block{snowy:false}"},
        {pos: [0, 12, 7], state: "minecraft:cornflower"},
        {pos: [0, 12, 8], state: "minecraft:grass_block{snowy:false}"},
        {pos: [0, 12, 9], state: "minecraft:grass_block{snowy:false}"},
        {pos: [1, 12, 6], state: "minecraft:grass_block{snowy:false}"},
        {pos: [1, 12, 7], state: "minecraft:dark_oak_sign{rotation:12,waterlogged:false}", nbt: {ForgeCaps: {}, back_text: {color: "black", has_glowing_text: 0b, messages: ['{"text":""}', '{"text":""}', '{"text":""}', '{"text":""}']}, front_text: {color: "black", has_glowing_text: 1b, messages: ['{"text":"Welcome to"}', '{"text":"Potato Island!"}', '{"text":"Everything you"}', '{"text":"need to start!"}']}, id: "minecraft:sign", is_waxed: 0b}},
        {pos: [1, 12, 9], state: "minecraft:grass_block{snowy:false}"},
        {pos: [1, 12, 10], state: "minecraft:grass_block{snowy:false}"},
        {pos: [2, 12, 6], state: "minecraft:grass"},
        {pos: [2, 12, 9], state: "minecraft:grass"},
        {pos: [2, 12, 11], state: "minecraft:grass_block{snowy:false}"},
        {pos: [3, 12, 4], state: "minecraft:tall_grass{half:upper}"},
        {pos: [3, 12, 5], state: "minecraft:tall_grass{half:upper}"},
        {pos: [3, 12, 9], state: "minecraft:tall_grass{half:upper}"},
        {pos: [3, 12, 11], state: "minecraft:tall_grass{half:upper}"},
        {pos: [4, 12, 5], state: "minecraft:tall_grass{half:upper}"},
        {pos: [5, 12, 5], state: "minecraft:tall_grass{half:upper}"},
        {pos: [6, 12, 7], state: "minecraft:oak_log{axis:y}"},
        {pos: [6, 12, 8], state: "minecraft:tall_grass{half:upper}"},
        {pos: [7, 12, 6], state: "minecraft:tall_grass{half:upper}"},
        {pos: [0, 13, 6], state: "minecraft:dandelion"},
        {pos: [0, 13, 8], state: "minecraft:grass"},
        {pos: [0, 13, 9], state: "minecraft:grass"},
        {pos: [1, 13, 6], state: "minecraft:tall_grass{half:lower}"},
        {pos: [1, 13, 9], state: "minecraft:tall_grass{half:lower}"},
        {pos: [1, 13, 10], state: "minecraft:poppy"},
        {pos: [2, 13, 11], state: "minecraft:tall_grass{half:lower}"},
        {pos: [6, 13, 7], state: "minecraft:oak_log{axis:y}"},
        {pos: [1, 14, 6], state: "minecraft:tall_grass{half:upper}"},
        {pos: [1, 14, 9], state: "minecraft:tall_grass{half:upper}"},
        {pos: [2, 14, 11], state: "minecraft:tall_grass{half:upper}"},
        {pos: [6, 14, 7], state: "minecraft:oak_log{axis:y}"},
        {pos: [7, 14, 7], state: "minecraft:bee_nest{facing:south,honey_level:5}", nbt: {Bees: [{EntityData:{id:"minecraft:bee"}},{EntityData:{id:"minecraft:bee"}},{EntityData:{id:"minecraft:bee"}}], FlowerPos: {X: 8197, Y: 64, Z: 8201}, ForgeCaps: {}, id: "minecraft:beehive"}},
        {pos: [5, 15, 6], state: "minecraft:oak_leaves{distance:1,persistent:false,waterlogged:false}"},
        {pos: [6, 15, 5], state: "minecraft:oak_leaves{distance:1,persistent:false,waterlogged:false}"},
        {pos: [6, 15, 6], state: "minecraft:oak_log{axis:z}"},
        {pos: [6, 15, 7], state: "minecraft:oak_log{axis:y}"},
        {pos: [7, 15, 6], state: "minecraft:oak_leaves{distance:1,persistent:false,waterlogged:false}"},
        {pos: [3, 16, 6], state: "minecraft:oak_leaves{distance:1,persistent:false,waterlogged:false}"},
        {pos: [4, 16, 5], state: "minecraft:oak_leaves{distance:1,persistent:false,waterlogged:false}"},
        {pos: [4, 16, 6], state: "minecraft:oak_log{axis:x}"},
        {pos: [4, 16, 7], state: "minecraft:oak_leaves{distance:1,persistent:false,waterlogged:false}"},
        {pos: [5, 16, 4], state: "minecraft:oak_leaves{distance:1,persistent:false,waterlogged:false}"},
        {pos: [5, 16, 5], state: "minecraft:oak_leaves{distance:1,persistent:false,waterlogged:false}"},
        {pos: [5, 16, 6], state: "minecraft:oak_leaves{distance:1,persistent:false,waterlogged:false}"},
        {pos: [5, 16, 7], state: "minecraft:oak_log{axis:x}"},
        {pos: [5, 16, 8], state: "minecraft:oak_leaves{distance:1,persistent:false,waterlogged:false}"},
        {pos: [6, 16, 4], state: "minecraft:oak_log{axis:z}"},
        {pos: [6, 16, 5], state: "minecraft:oak_log{axis:z}"},
        {pos: [6, 16, 6], state: "minecraft:oak_leaves{distance:1,persistent:false,waterlogged:false}"},
        {pos: [6, 16, 7], state: "minecraft:oak_log{axis:y}"},
        {pos: [6, 16, 8], state: "minecraft:oak_leaves{distance:1,persistent:false,waterlogged:false}"},
        {pos: [7, 16, 4], state: "minecraft:oak_leaves{distance:1,persistent:false,waterlogged:false}"},
        {pos: [7, 16, 5], state: "minecraft:oak_leaves{distance:1,persistent:false,waterlogged:false}"},
        {pos: [7, 16, 6], state: "minecraft:oak_leaves{distance:2,persistent:false,waterlogged:false}"},
        {pos: [7, 16, 7], state: "minecraft:oak_leaves{distance:1,persistent:false,waterlogged:false}"},
        {pos: [7, 16, 8], state: "minecraft:oak_leaves{distance:2,persistent:false,waterlogged:false}"},
        {pos: [8, 16, 5], state: "minecraft:oak_leaves{distance:2,persistent:false,waterlogged:false}"},
        {pos: [8, 16, 6], state: "minecraft:oak_leaves{distance:3,persistent:false,waterlogged:false}"},
        {pos: [8, 16, 7], state: "minecraft:oak_leaves{distance:2,persistent:false,waterlogged:false}"},
        {pos: [2, 17, 5], state: "minecraft:oak_leaves{distance:3,persistent:false,waterlogged:false}"},
        {pos: [2, 17, 6], state: "minecraft:oak_leaves{distance:3,persistent:false,waterlogged:false}"},
        {pos: [2, 17, 7], state: "minecraft:oak_leaves{distance:4,persistent:false,waterlogged:false}"},
        {pos: [3, 17, 4], state: "minecraft:oak_leaves{distance:2,persistent:false,waterlogged:false}"},
        {pos: [3, 17, 5], state: "minecraft:oak_leaves{distance:2,persistent:false,waterlogged:false}"},
        {pos: [3, 17, 6], state: "minecraft:oak_leaves{distance:2,persistent:false,waterlogged:false}"},
        {pos: [3, 17, 7], state: "minecraft:oak_leaves{distance:3,persistent:false,waterlogged:false}"},
        {pos: [3, 17, 8], state: "minecraft:oak_leaves{distance:3,persistent:false,waterlogged:false}"},
        {pos: [4, 17, 4], state: "minecraft:oak_leaves{distance:1,persistent:false,waterlogged:false}"},
        {pos: [4, 17, 5], state: "minecraft:oak_leaves{distance:1,persistent:false,waterlogged:false}"},
        {pos: [4, 17, 6], state: "minecraft:oak_leaves{distance:1,persistent:false,waterlogged:false}"},
        {pos: [4, 17, 7], state: "minecraft:oak_leaves{distance:2,persistent:false,waterlogged:false}"},
        {pos: [4, 17, 8], state: "minecraft:oak_leaves{distance:2,persistent:false,waterlogged:false}"},
        {pos: [5, 17, 2], state: "minecraft:oak_leaves{distance:1,persistent:false,waterlogged:false}"},
        {pos: [5, 17, 4], state: "minecraft:oak_leaves{distance:1,persistent:false,waterlogged:false}"},
        {pos: [5, 17, 5], state: "minecraft:oak_log{axis:z}"},
        {pos: [5, 17, 6], state: "minecraft:oak_log{axis:x}"},
        {pos: [5, 17, 7], state: "minecraft:oak_leaves{distance:1,persistent:false,waterlogged:false}"},
        {pos: [5, 17, 8], state: "minecraft:oak_leaves{distance:1,persistent:false,waterlogged:false}"},
        {pos: [6, 17, 1], state: "minecraft:oak_leaves{distance:1,persistent:false,waterlogged:false}"},
        {pos: [6, 17, 2], state: "minecraft:oak_log{axis:z}"},
        {pos: [6, 17, 3], state: "minecraft:oak_log{axis:z}"},
        {pos: [6, 17, 4], state: "minecraft:oak_leaves{distance:1,persistent:false,waterlogged:false}"},
        {pos: [6, 17, 5], state: "minecraft:oak_leaves{distance:1,persistent:false,waterlogged:false}"},
        {pos: [6, 17, 6], state: "minecraft:oak_leaves{distance:1,persistent:false,waterlogged:false}"},
        {pos: [6, 17, 7], state: "minecraft:oak_log{axis:y}"},
        {pos: [6, 17, 8], state: "minecraft:oak_log{axis:z}"},
        {pos: [7, 17, 2], state: "minecraft:oak_leaves{distance:1,persistent:false,waterlogged:false}"},
        {pos: [7, 17, 4], state: "minecraft:oak_leaves{distance:2,persistent:false,waterlogged:false}"},
        {pos: [7, 17, 5], state: "minecraft:oak_leaves{distance:2,persistent:false,waterlogged:false}"},
        {pos: [7, 17, 6], state: "minecraft:oak_leaves{distance:2,persistent:false,waterlogged:false}"},
        {pos: [7, 17, 7], state: "minecraft:oak_leaves{distance:1,persistent:false,waterlogged:false}"},
        {pos: [7, 17, 8], state: "minecraft:oak_leaves{distance:1,persistent:false,waterlogged:false}"},
        {pos: [8, 17, 5], state: "minecraft:oak_leaves{distance:3,persistent:false,waterlogged:false}"},
        {pos: [8, 17, 6], state: "minecraft:oak_leaves{distance:3,persistent:false,waterlogged:false}"},
        {pos: [8, 17, 7], state: "minecraft:oak_leaves{distance:2,persistent:false,waterlogged:false}"},
        {pos: [2, 18, 5], state: "minecraft:oak_leaves{distance:3,persistent:false,waterlogged:false}"},
        {pos: [2, 18, 6], state: "minecraft:oak_leaves{distance:4,persistent:false,waterlogged:false}"},
        {pos: [2, 18, 7], state: "minecraft:oak_leaves{distance:4,persistent:false,waterlogged:false}"},
        {pos: [3, 18, 4], state: "minecraft:oak_leaves{distance:1,persistent:false,waterlogged:false}"},
        {pos: [3, 18, 5], state: "minecraft:oak_leaves{distance:2,persistent:false,waterlogged:false}"},
        {pos: [3, 18, 6], state: "minecraft:oak_leaves{distance:3,persistent:false,waterlogged:false}"},
        {pos: [3, 18, 7], state: "minecraft:oak_leaves{distance:3,persistent:false,waterlogged:false}"},
        {pos: [3, 18, 8], state: "minecraft:oak_leaves{distance:4,persistent:false,waterlogged:false}"},
        {pos: [4, 18, 1], state: "minecraft:oak_leaves{distance:3,persistent:false,waterlogged:false}"},
        {pos: [4, 18, 2], state: "minecraft:oak_leaves{distance:2,persistent:false,waterlogged:false}"},
        {pos: [4, 18, 3], state: "minecraft:oak_leaves{distance:1,persistent:false,waterlogged:false}"},
        {pos: [4, 18, 4], state: "minecraft:oak_log{axis:z}"},
        {pos: [4, 18, 5], state: "minecraft:oak_leaves{distance:1,persistent:false,waterlogged:false}"},
        {pos: [4, 18, 6], state: "minecraft:oak_leaves{distance:2,persistent:false,waterlogged:false}"},
        {pos: [4, 18, 7], state: "minecraft:oak_leaves{distance:2,persistent:false,waterlogged:false}"},
        {pos: [4, 18, 8], state: "minecraft:oak_leaves{distance:3,persistent:false,waterlogged:false}"},
        {pos: [5, 18, 0], state: "minecraft:oak_leaves{distance:4,persistent:false,waterlogged:false}"},
        {pos: [5, 18, 1], state: "minecraft:oak_leaves{distance:3,persistent:false,waterlogged:false}"},
        {pos: [5, 18, 2], state: "minecraft:oak_leaves{distance:2,persistent:false,waterlogged:false}"},
        {pos: [5, 18, 3], state: "minecraft:oak_leaves{distance:2,persistent:false,waterlogged:false}"},
        {pos: [5, 18, 4], state: "minecraft:oak_leaves{distance:1,persistent:false,waterlogged:false}"},
        {pos: [5, 18, 5], state: "minecraft:oak_leaves{distance:1,persistent:false,waterlogged:false}"},
        {pos: [5, 18, 6], state: "minecraft:oak_leaves{distance:1,persistent:false,waterlogged:false}"},
        {pos: [5, 18, 7], state: "minecraft:oak_leaves{distance:1,persistent:false,waterlogged:false}"},
        {pos: [5, 18, 8], state: "minecraft:oak_leaves{distance:2,persistent:false,waterlogged:false}"},
        {pos: [6, 18, 0], state: "minecraft:oak_leaves{distance:3,persistent:false,waterlogged:false}"},
        {pos: [6, 18, 1], state: "minecraft:oak_leaves{distance:2,persistent:false,waterlogged:false}"},
        {pos: [6, 18, 2], state: "minecraft:oak_leaves{distance:1,persistent:false,waterlogged:false}"},
        {pos: [6, 18, 3], state: "minecraft:oak_leaves{distance:1,persistent:false,waterlogged:false}"},
        {pos: [6, 18, 4], state: "minecraft:oak_leaves{distance:2,persistent:false,waterlogged:false}"},
        {pos: [6, 18, 5], state: "minecraft:oak_leaves{distance:2,persistent:false,waterlogged:false}"},
        {pos: [6, 18, 6], state: "minecraft:oak_leaves{distance:1,persistent:false,waterlogged:false}"},
        {pos: [6, 18, 7], state: "minecraft:oak_log{axis:y}"},
        {pos: [6, 18, 8], state: "minecraft:oak_leaves{distance:1,persistent:false,waterlogged:false}"},
        {pos: [6, 18, 9], state: "minecraft:oak_log{axis:z}"},
        {pos: [6, 18, 10], state: "minecraft:oak_log{axis:z}"},
        {pos: [7, 18, 0], state: "minecraft:oak_leaves{distance:4,persistent:false,waterlogged:false}"},
        {pos: [7, 18, 1], state: "minecraft:oak_leaves{distance:3,persistent:false,waterlogged:false}"},
        {pos: [7, 18, 2], state: "minecraft:oak_leaves{distance:2,persistent:false,waterlogged:false}"},
        {pos: [7, 18, 3], state: "minecraft:oak_leaves{distance:2,persistent:false,waterlogged:false}"},
        {pos: [7, 18, 4], state: "minecraft:oak_leaves{distance:3,persistent:false,waterlogged:false}"},
        {pos: [7, 18, 5], state: "minecraft:oak_leaves{distance:3,persistent:false,waterlogged:false}"},
        {pos: [7, 18, 6], state: "minecraft:oak_leaves{distance:2,persistent:false,waterlogged:false}"},
        {pos: [7, 18, 7], state: "minecraft:oak_leaves{distance:1,persistent:false,waterlogged:false}"},
        {pos: [7, 18, 8], state: "minecraft:oak_leaves{distance:2,persistent:false,waterlogged:false}"},
        {pos: [8, 18, 1], state: "minecraft:oak_leaves{distance:4,persistent:false,waterlogged:false}"},
        {pos: [8, 18, 2], state: "minecraft:oak_leaves{distance:3,persistent:false,waterlogged:false}"},
        {pos: [8, 18, 3], state: "minecraft:oak_leaves{distance:3,persistent:false,waterlogged:false}"},
        {pos: [8, 18, 5], state: "minecraft:oak_leaves{distance:4,persistent:false,waterlogged:false}"},
        {pos: [8, 18, 6], state: "minecraft:oak_leaves{distance:3,persistent:false,waterlogged:false}"},
        {pos: [8, 18, 7], state: "minecraft:oak_leaves{distance:2,persistent:false,waterlogged:false}"},
        {pos: [2, 19, 3], state: "minecraft:oak_leaves{distance:4,persistent:false,waterlogged:false}"},
        {pos: [2, 19, 4], state: "minecraft:oak_leaves{distance:3,persistent:false,waterlogged:false}"},
        {pos: [2, 19, 5], state: "minecraft:oak_leaves{distance:4,persistent:false,waterlogged:false}"},
        {pos: [2, 19, 6], state: "minecraft:oak_leaves{distance:5,persistent:false,waterlogged:false}"},
        {pos: [2, 19, 7], state: "minecraft:oak_leaves{distance:4,persistent:false,waterlogged:false}"},
        {pos: [3, 19, 2], state: "minecraft:oak_leaves{distance:4,persistent:false,waterlogged:false}"},
        {pos: [3, 19, 3], state: "minecraft:oak_leaves{distance:3,persistent:false,waterlogged:false}"},
        {pos: [3, 19, 4], state: "minecraft:oak_leaves{distance:2,persistent:false,waterlogged:false}"},
        {pos: [3, 19, 5], state: "minecraft:oak_leaves{distance:3,persistent:false,waterlogged:false}"},
        {pos: [3, 19, 6], state: "minecraft:oak_leaves{distance:4,persistent:false,waterlogged:false}"},
        {pos: [3, 19, 7], state: "minecraft:oak_leaves{distance:3,persistent:false,waterlogged:false}"},
        {pos: [3, 19, 8], state: "minecraft:oak_leaves{distance:4,persistent:false,waterlogged:false}"},
        {pos: [4, 19, 1], state: "minecraft:oak_leaves{distance:4,persistent:false,waterlogged:false}"},
        {pos: [4, 19, 2], state: "minecraft:oak_leaves{distance:3,persistent:false,waterlogged:false}"},
        {pos: [4, 19, 3], state: "minecraft:oak_leaves{distance:2,persistent:false,waterlogged:false}"},
        {pos: [4, 19, 4], state: "minecraft:oak_leaves{distance:1,persistent:false,waterlogged:false}"},
        {pos: [4, 19, 5], state: "minecraft:oak_leaves{distance:2,persistent:false,waterlogged:false}"},
        {pos: [4, 19, 6], state: "minecraft:oak_leaves{distance:3,persistent:false,waterlogged:false}"},
        {pos: [4, 19, 7], state: "minecraft:oak_leaves{distance:2,persistent:false,waterlogged:false}"},
        {pos: [4, 19, 8], state: "minecraft:oak_leaves{distance:3,persistent:false,waterlogged:false}"},
        {pos: [5, 19, 0], state: "minecraft:oak_leaves{distance:5,persistent:false,waterlogged:false}"},
        {pos: [5, 19, 1], state: "minecraft:oak_leaves{distance:4,persistent:false,waterlogged:false}"},
        {pos: [5, 19, 2], state: "minecraft:oak_leaves{distance:3,persistent:false,waterlogged:false}"},
        {pos: [5, 19, 3], state: "minecraft:oak_leaves{distance:3,persistent:false,waterlogged:false}"},
        {pos: [5, 19, 4], state: "minecraft:oak_leaves{distance:2,persistent:false,waterlogged:false}"},
        {pos: [5, 19, 5], state: "minecraft:oak_leaves{distance:2,persistent:false,waterlogged:false}"},
        {pos: [5, 19, 6], state: "minecraft:oak_leaves{distance:2,persistent:false,waterlogged:false}"},
        {pos: [5, 19, 7], state: "minecraft:oak_leaves{distance:1,persistent:false,waterlogged:false}"},
        {pos: [5, 19, 8], state: "minecraft:oak_leaves{distance:2,persistent:false,waterlogged:false}"},
        {pos: [5, 19, 12], state: "minecraft:oak_leaves{distance:1,persistent:false,waterlogged:false}"},
        {pos: [6, 19, 0], state: "minecraft:oak_leaves{distance:4,persistent:false,waterlogged:false}"},
        {pos: [6, 19, 1], state: "minecraft:oak_leaves{distance:3,persistent:false,waterlogged:false}"},
        {pos: [6, 19, 2], state: "minecraft:oak_leaves{distance:2,persistent:false,waterlogged:false}"},
        {pos: [6, 19, 3], state: "minecraft:oak_leaves{distance:2,persistent:false,waterlogged:false}"},
        {pos: [6, 19, 4], state: "minecraft:oak_leaves{distance:3,persistent:false,waterlogged:false}"},
        {pos: [6, 19, 5], state: "minecraft:oak_leaves{distance:2,persistent:false,waterlogged:false}"},
        {pos: [6, 19, 6], state: "minecraft:oak_leaves{distance:1,persistent:false,waterlogged:false}"},
        {pos: [6, 19, 7], state: "minecraft:oak_log{axis:y}"},
        {pos: [6, 19, 11], state: "minecraft:oak_log{axis:z}"},
        {pos: [6, 19, 12], state: "minecraft:oak_log{axis:z}"},
        {pos: [6, 19, 13], state: "minecraft:oak_leaves{distance:1,persistent:false,waterlogged:false}"},
        {pos: [7, 19, 0], state: "minecraft:oak_leaves{distance:5,persistent:false,waterlogged:false}"},
        {pos: [7, 19, 1], state: "minecraft:oak_leaves{distance:4,persistent:false,waterlogged:false}"},
        {pos: [7, 19, 2], state: "minecraft:oak_leaves{distance:3,persistent:false,waterlogged:false}"},
        {pos: [7, 19, 3], state: "minecraft:oak_leaves{distance:3,persistent:false,waterlogged:false}"},
        {pos: [7, 19, 4], state: "minecraft:oak_leaves{distance:4,persistent:false,waterlogged:false}"},
        {pos: [7, 19, 6], state: "minecraft:oak_leaves{distance:2,persistent:false,waterlogged:false}"},
        {pos: [7, 19, 12], state: "minecraft:oak_leaves{distance:1,persistent:false,waterlogged:false}"},
        {pos: [8, 19, 1], state: "minecraft:oak_leaves{distance:5,persistent:false,waterlogged:false}"},
        {pos: [8, 19, 2], state: "minecraft:oak_leaves{distance:4,persistent:false,waterlogged:false}"},
        {pos: [8, 19, 3], state: "minecraft:oak_leaves{distance:4,persistent:false,waterlogged:false}"},
        {pos: [2, 20, 3], state: "minecraft:oak_leaves{distance:5,persistent:false,waterlogged:false}"},
        {pos: [2, 20, 4], state: "minecraft:oak_leaves{distance:4,persistent:false,waterlogged:false}"},
        {pos: [2, 20, 5], state: "minecraft:oak_leaves{distance:5,persistent:false,waterlogged:false}"},
        {pos: [3, 20, 2], state: "minecraft:oak_leaves{distance:5,persistent:false,waterlogged:false}"},
        {pos: [3, 20, 3], state: "minecraft:oak_leaves{distance:4,persistent:false,waterlogged:false}"},
        {pos: [3, 20, 4], state: "minecraft:oak_leaves{distance:3,persistent:false,waterlogged:false}"},
        {pos: [3, 20, 5], state: "minecraft:oak_leaves{distance:4,persistent:false,waterlogged:false}"},
        {pos: [3, 20, 6], state: "minecraft:oak_leaves{distance:3,persistent:false,waterlogged:false}"},
        {pos: [4, 20, 1], state: "minecraft:oak_leaves{distance:5,persistent:false,waterlogged:false}"},
        {pos: [4, 20, 2], state: "minecraft:oak_leaves{distance:4,persistent:false,waterlogged:false}"},
        {pos: [4, 20, 3], state: "minecraft:oak_leaves{distance:3,persistent:false,waterlogged:false}"},
        {pos: [4, 20, 4], state: "minecraft:oak_leaves{distance:2,persistent:false,waterlogged:false}"},
        {pos: [4, 20, 5], state: "minecraft:oak_leaves{distance:3,persistent:false,waterlogged:false}"},
        {pos: [4, 20, 6], state: "minecraft:oak_leaves{distance:2,persistent:false,waterlogged:false}"},
        {pos: [4, 20, 7], state: "minecraft:oak_leaves{distance:3,persistent:false,waterlogged:false}"},
        {pos: [4, 20, 11], state: "minecraft:oak_leaves{distance:3,persistent:false,waterlogged:false}"},
        {pos: [4, 20, 12], state: "minecraft:oak_leaves{distance:3,persistent:false,waterlogged:false}"},
        {pos: [4, 20, 13], state: "minecraft:oak_leaves{distance:4,persistent:false,waterlogged:false}"},
        {pos: [5, 20, 0], state: "minecraft:oak_leaves{distance:6,persistent:false,waterlogged:false}"},
        {pos: [5, 20, 1], state: "minecraft:oak_leaves{distance:5,persistent:false,waterlogged:false}"},
        {pos: [5, 20, 2], state: "minecraft:oak_leaves{distance:4,persistent:false,waterlogged:false}"},
        {pos: [5, 20, 3], state: "minecraft:oak_leaves{distance:4,persistent:false,waterlogged:false}"},
        {pos: [5, 20, 4], state: "minecraft:oak_leaves{distance:3,persistent:false,waterlogged:false}"},
        {pos: [5, 20, 5], state: "minecraft:oak_leaves{distance:2,persistent:false,waterlogged:false}"},
        {pos: [5, 20, 6], state: "minecraft:oak_leaves{distance:1,persistent:false,waterlogged:false}"},
        {pos: [5, 20, 10], state: "minecraft:oak_leaves{distance:3,persistent:false,waterlogged:false}"},
        {pos: [5, 20, 11], state: "minecraft:oak_leaves{distance:2,persistent:false,waterlogged:false}"},
        {pos: [5, 20, 12], state: "minecraft:oak_leaves{distance:2,persistent:false,waterlogged:false}"},
        {pos: [5, 20, 13], state: "minecraft:oak_leaves{distance:3,persistent:false,waterlogged:false}"},
        {pos: [5, 20, 14], state: "minecraft:oak_leaves{distance:4,persistent:false,waterlogged:false}"},
        {pos: [6, 20, 0], state: "minecraft:oak_leaves{distance:5,persistent:false,waterlogged:false}"},
        {pos: [6, 20, 1], state: "minecraft:oak_leaves{distance:4,persistent:false,waterlogged:false}"},
        {pos: [6, 20, 2], state: "minecraft:oak_leaves{distance:3,persistent:false,waterlogged:false}"},
        {pos: [6, 20, 3], state: "minecraft:oak_leaves{distance:3,persistent:false,waterlogged:false}"},
        {pos: [6, 20, 4], state: "minecraft:oak_leaves{distance:2,persistent:false,waterlogged:false}"},
        {pos: [6, 20, 5], state: "minecraft:oak_leaves{distance:1,persistent:false,waterlogged:false}"},
        {pos: [6, 20, 6], state: "minecraft:oak_log{axis:z}"},
        {pos: [6, 20, 7], state: "minecraft:oak_log{axis:y}"},
        {pos: [6, 20, 10], state: "minecraft:oak_leaves{distance:2,persistent:false,waterlogged:false}"},
        {pos: [6, 20, 11], state: "minecraft:oak_leaves{distance:1,persistent:false,waterlogged:false}"},
        {pos: [6, 20, 12], state: "minecraft:oak_leaves{distance:1,persistent:false,waterlogged:false}"},
        {pos: [6, 20, 13], state: "minecraft:oak_leaves{distance:2,persistent:false,waterlogged:false}"},
        {pos: [6, 20, 14], state: "minecraft:oak_leaves{distance:3,persistent:false,waterlogged:false}"},
        {pos: [7, 20, 0], state: "minecraft:oak_leaves{distance:6,persistent:false,waterlogged:false}"},
        {pos: [7, 20, 1], state: "minecraft:oak_leaves{distance:5,persistent:false,waterlogged:false}"},
        {pos: [7, 20, 2], state: "minecraft:oak_leaves{distance:4,persistent:false,waterlogged:false}"},
        {pos: [7, 20, 3], state: "minecraft:oak_leaves{distance:4,persistent:false,waterlogged:false}"},
        {pos: [7, 20, 4], state: "minecraft:oak_leaves{distance:3,persistent:false,waterlogged:false}"},
        {pos: [7, 20, 6], state: "minecraft:oak_leaves{distance:1,persistent:false,waterlogged:false}"},
        {pos: [7, 20, 10], state: "minecraft:oak_leaves{distance:3,persistent:false,waterlogged:false}"},
        {pos: [7, 20, 11], state: "minecraft:oak_leaves{distance:2,persistent:false,waterlogged:false}"},
        {pos: [7, 20, 12], state: "minecraft:oak_leaves{distance:2,persistent:false,waterlogged:false}"},
        {pos: [7, 20, 13], state: "minecraft:oak_leaves{distance:3,persistent:false,waterlogged:false}"},
        {pos: [7, 20, 14], state: "minecraft:oak_leaves{distance:4,persistent:false,waterlogged:false}"},
        {pos: [8, 20, 1], state: "minecraft:oak_leaves{distance:6,persistent:false,waterlogged:false}"},
        {pos: [8, 20, 2], state: "minecraft:oak_leaves{distance:5,persistent:false,waterlogged:false}"},
        {pos: [8, 20, 3], state: "minecraft:oak_leaves{distance:5,persistent:false,waterlogged:false}"},
        {pos: [8, 20, 11], state: "minecraft:oak_leaves{distance:3,persistent:false,waterlogged:false}"},
        {pos: [8, 20, 12], state: "minecraft:oak_leaves{distance:3,persistent:false,waterlogged:false}"},
        {pos: [8, 20, 13], state: "minecraft:oak_leaves{distance:4,persistent:false,waterlogged:false}"},
        {pos: [2, 21, 3], state: "minecraft:oak_leaves{distance:6,persistent:false,waterlogged:false}"},
        {pos: [2, 21, 4], state: "minecraft:oak_leaves{distance:5,persistent:false,waterlogged:false}"},
        {pos: [2, 21, 5], state: "minecraft:oak_leaves{distance:6,persistent:false,waterlogged:false}"},
        {pos: [3, 21, 2], state: "minecraft:oak_leaves{distance:6,persistent:false,waterlogged:false}"},
        {pos: [3, 21, 3], state: "minecraft:oak_leaves{distance:5,persistent:false,waterlogged:false}"},
        {pos: [3, 21, 4], state: "minecraft:oak_leaves{distance:4,persistent:false,waterlogged:false}"},
        {pos: [3, 21, 5], state: "minecraft:oak_leaves{distance:5,persistent:false,waterlogged:false}"},
        {pos: [3, 21, 6], state: "minecraft:oak_leaves{distance:4,persistent:false,waterlogged:false}"},
        {pos: [4, 21, 2], state: "minecraft:oak_leaves{distance:5,persistent:false,waterlogged:false}"},
        {pos: [4, 21, 3], state: "minecraft:oak_leaves{distance:4,persistent:false,waterlogged:false}"},
        {pos: [4, 21, 4], state: "minecraft:oak_leaves{distance:3,persistent:false,waterlogged:false}"},
        {pos: [4, 21, 5], state: "minecraft:oak_leaves{distance:4,persistent:false,waterlogged:false}"},
        {pos: [4, 21, 6], state: "minecraft:oak_leaves{distance:3,persistent:false,waterlogged:false}"},
        {pos: [4, 21, 7], state: "minecraft:oak_leaves{distance:2,persistent:false,waterlogged:false}"},
        {pos: [4, 21, 11], state: "minecraft:oak_leaves{distance:4,persistent:false,waterlogged:false}"},
        {pos: [4, 21, 12], state: "minecraft:oak_leaves{distance:4,persistent:false,waterlogged:false}"},
        {pos: [4, 21, 13], state: "minecraft:oak_leaves{distance:5,persistent:false,waterlogged:false}"},
        {pos: [5, 21, 2], state: "minecraft:oak_leaves{distance:5,persistent:false,waterlogged:false}"},
        {pos: [5, 21, 3], state: "minecraft:oak_leaves{distance:5,persistent:false,waterlogged:false}"},
        {pos: [5, 21, 4], state: "minecraft:oak_leaves{distance:4,persistent:false,waterlogged:false}"},
        {pos: [5, 21, 5], state: "minecraft:oak_leaves{distance:3,persistent:false,waterlogged:false}"},
        {pos: [5, 21, 6], state: "minecraft:oak_leaves{distance:2,persistent:false,waterlogged:false}"},
        {pos: [5, 21, 7], state: "minecraft:oak_leaves{distance:1,persistent:false,waterlogged:false}"},
        {pos: [5, 21, 8], state: "minecraft:oak_leaves{distance:2,persistent:false,waterlogged:false}"},
        {pos: [5, 21, 10], state: "minecraft:oak_leaves{distance:4,persistent:false,waterlogged:false}"},
        {pos: [5, 21, 11], state: "minecraft:oak_leaves{distance:3,persistent:false,waterlogged:false}"},
        {pos: [5, 21, 12], state: "minecraft:oak_leaves{distance:3,persistent:false,waterlogged:false}"},
        {pos: [5, 21, 13], state: "minecraft:oak_leaves{distance:4,persistent:false,waterlogged:false}"},
        {pos: [5, 21, 14], state: "minecraft:oak_leaves{distance:5,persistent:false,waterlogged:false}"},
        {pos: [6, 21, 1], state: "minecraft:oak_leaves{distance:5,persistent:false,waterlogged:false}"},
        {pos: [6, 21, 2], state: "minecraft:oak_leaves{distance:4,persistent:false,waterlogged:false}"},
        {pos: [6, 21, 3], state: "minecraft:oak_leaves{distance:4,persistent:false,waterlogged:false}"},
        {pos: [6, 21, 4], state: "minecraft:oak_leaves{distance:3,persistent:false,waterlogged:false}"},
        {pos: [6, 21, 5], state: "minecraft:oak_leaves{distance:2,persistent:false,waterlogged:false}"},
        {pos: [6, 21, 6], state: "minecraft:oak_leaves{distance:1,persistent:false,waterlogged:false}"},
        {pos: [6, 21, 7], state: "minecraft:oak_log{axis:y}"},
        {pos: [6, 21, 8], state: "minecraft:oak_leaves{distance:1,persistent:false,waterlogged:false}"},
        {pos: [6, 21, 10], state: "minecraft:oak_leaves{distance:3,persistent:false,waterlogged:false}"},
        {pos: [6, 21, 11], state: "minecraft:oak_leaves{distance:2,persistent:false,waterlogged:false}"},
        {pos: [6, 21, 12], state: "minecraft:oak_leaves{distance:2,persistent:false,waterlogged:false}"},
        {pos: [6, 21, 13], state: "minecraft:oak_leaves{distance:3,persistent:false,waterlogged:false}"},
        {pos: [6, 21, 14], state: "minecraft:oak_leaves{distance:4,persistent:false,waterlogged:false}"},
        {pos: [7, 21, 2], state: "minecraft:oak_leaves{distance:5,persistent:false,waterlogged:false}"},
        {pos: [7, 21, 4], state: "minecraft:oak_leaves{distance:4,persistent:false,waterlogged:false}"},
        {pos: [7, 21, 5], state: "minecraft:oak_leaves{distance:3,persistent:false,waterlogged:false}"},
        {pos: [7, 21, 6], state: "minecraft:oak_leaves{distance:2,persistent:false,waterlogged:false}"},
        {pos: [7, 21, 7], state: "minecraft:oak_leaves{distance:1,persistent:false,waterlogged:false}"},
        {pos: [7, 21, 8], state: "minecraft:oak_leaves{distance:2,persistent:false,waterlogged:false}"},
        {pos: [7, 21, 10], state: "minecraft:oak_leaves{distance:4,persistent:false,waterlogged:false}"},
        {pos: [7, 21, 11], state: "minecraft:oak_leaves{distance:3,persistent:false,waterlogged:false}"},
        {pos: [7, 21, 12], state: "minecraft:oak_leaves{distance:3,persistent:false,waterlogged:false}"},
        {pos: [7, 21, 13], state: "minecraft:oak_leaves{distance:4,persistent:false,waterlogged:false}"},
        {pos: [7, 21, 14], state: "minecraft:oak_leaves{distance:5,persistent:false,waterlogged:false}"},
        {pos: [8, 21, 5], state: "minecraft:oak_leaves{distance:4,persistent:false,waterlogged:false}"},
        {pos: [8, 21, 6], state: "minecraft:oak_leaves{distance:3,persistent:false,waterlogged:false}"},
        {pos: [8, 21, 7], state: "minecraft:oak_leaves{distance:2,persistent:false,waterlogged:false}"},
        {pos: [8, 21, 11], state: "minecraft:oak_leaves{distance:4,persistent:false,waterlogged:false}"},
        {pos: [8, 21, 12], state: "minecraft:oak_leaves{distance:4,persistent:false,waterlogged:false}"},
        {pos: [8, 21, 13], state: "minecraft:oak_leaves{distance:5,persistent:false,waterlogged:false}"},
        {pos: [3, 22, 4], state: "minecraft:oak_leaves{distance:5,persistent:false,waterlogged:false}"},
        {pos: [4, 22, 3], state: "minecraft:oak_leaves{distance:5,persistent:false,waterlogged:false}"},
        {pos: [4, 22, 4], state: "minecraft:oak_leaves{distance:4,persistent:false,waterlogged:false}"},
        {pos: [4, 22, 5], state: "minecraft:oak_leaves{distance:5,persistent:false,waterlogged:false}"},
        {pos: [4, 22, 6], state: "minecraft:oak_leaves{distance:4,persistent:false,waterlogged:false}"},
        {pos: [4, 22, 7], state: "minecraft:oak_leaves{distance:3,persistent:false,waterlogged:false}"},
        {pos: [4, 22, 8], state: "minecraft:oak_leaves{distance:4,persistent:false,waterlogged:false}"},
        {pos: [4, 22, 11], state: "minecraft:oak_leaves{distance:5,persistent:false,waterlogged:false}"},
        {pos: [4, 22, 12], state: "minecraft:oak_leaves{distance:5,persistent:false,waterlogged:false}"},
        {pos: [4, 22, 13], state: "minecraft:oak_leaves{distance:6,persistent:false,waterlogged:false}"},
        {pos: [5, 22, 4], state: "minecraft:oak_leaves{distance:5,persistent:false,waterlogged:false}"},
        {pos: [5, 22, 5], state: "minecraft:oak_leaves{distance:4,persistent:false,waterlogged:false}"},
        {pos: [5, 22, 6], state: "minecraft:oak_leaves{distance:3,persistent:false,waterlogged:false}"},
        {pos: [5, 22, 7], state: "minecraft:oak_leaves{distance:2,persistent:false,waterlogged:false}"},
        {pos: [5, 22, 8], state: "minecraft:oak_leaves{distance:3,persistent:false,waterlogged:false}"},
        {pos: [5, 22, 9], state: "minecraft:oak_leaves{distance:4,persistent:false,waterlogged:false}"},
        {pos: [5, 22, 10], state: "minecraft:oak_leaves{distance:5,persistent:false,waterlogged:false}"},
        {pos: [5, 22, 11], state: "minecraft:oak_leaves{distance:4,persistent:false,waterlogged:false}"},
        {pos: [5, 22, 12], state: "minecraft:oak_leaves{distance:4,persistent:false,waterlogged:false}"},
        {pos: [5, 22, 13], state: "minecraft:oak_leaves{distance:5,persistent:false,waterlogged:false}"},
        {pos: [5, 22, 14], state: "minecraft:oak_leaves{distance:6,persistent:false,waterlogged:false}"},
        {pos: [6, 22, 4], state: "minecraft:oak_leaves{distance:4,persistent:false,waterlogged:false}"},
        {pos: [6, 22, 5], state: "minecraft:oak_leaves{distance:3,persistent:false,waterlogged:false}"},
        {pos: [6, 22, 6], state: "minecraft:oak_leaves{distance:2,persistent:false,waterlogged:false}"},
        {pos: [6, 22, 7], state: "minecraft:oak_leaves{distance:1,persistent:false,waterlogged:false}"},
        {pos: [6, 22, 8], state: "minecraft:oak_leaves{distance:2,persistent:false,waterlogged:false}"},
        {pos: [6, 22, 9], state: "minecraft:oak_leaves{distance:3,persistent:false,waterlogged:false}"},
        {pos: [6, 22, 10], state: "minecraft:oak_leaves{distance:4,persistent:false,waterlogged:false}"},
        {pos: [6, 22, 11], state: "minecraft:oak_leaves{distance:3,persistent:false,waterlogged:false}"},
        {pos: [6, 22, 12], state: "minecraft:oak_leaves{distance:3,persistent:false,waterlogged:false}"},
        {pos: [6, 22, 13], state: "minecraft:oak_leaves{distance:4,persistent:false,waterlogged:false}"},
        {pos: [6, 22, 14], state: "minecraft:oak_leaves{distance:5,persistent:false,waterlogged:false}"},
        {pos: [7, 22, 4], state: "minecraft:oak_leaves{distance:5,persistent:false,waterlogged:false}"},
        {pos: [7, 22, 5], state: "minecraft:oak_leaves{distance:4,persistent:false,waterlogged:false}"},
        {pos: [7, 22, 6], state: "minecraft:oak_leaves{distance:3,persistent:false,waterlogged:false}"},
        {pos: [7, 22, 7], state: "minecraft:oak_leaves{distance:2,persistent:false,waterlogged:false}"},
        {pos: [7, 22, 8], state: "minecraft:oak_leaves{distance:3,persistent:false,waterlogged:false}"},
        {pos: [7, 22, 9], state: "minecraft:oak_leaves{distance:4,persistent:false,waterlogged:false}"},
        {pos: [7, 22, 10], state: "minecraft:oak_leaves{distance:5,persistent:false,waterlogged:false}"},
        {pos: [7, 22, 11], state: "minecraft:oak_leaves{distance:4,persistent:false,waterlogged:false}"},
        {pos: [7, 22, 12], state: "minecraft:oak_leaves{distance:4,persistent:false,waterlogged:false}"},
        {pos: [7, 22, 13], state: "minecraft:oak_leaves{distance:5,persistent:false,waterlogged:false}"},
        {pos: [7, 22, 14], state: "minecraft:oak_leaves{distance:6,persistent:false,waterlogged:false}"},
        {pos: [8, 22, 5], state: "minecraft:oak_leaves{distance:5,persistent:false,waterlogged:false}"},
        {pos: [8, 22, 6], state: "minecraft:oak_leaves{distance:4,persistent:false,waterlogged:false}"},
        {pos: [8, 22, 7], state: "minecraft:oak_leaves{distance:3,persistent:false,waterlogged:false}"},
        {pos: [8, 22, 8], state: "minecraft:oak_leaves{distance:4,persistent:false,waterlogged:false}"},
        {pos: [8, 22, 11], state: "minecraft:oak_leaves{distance:5,persistent:false,waterlogged:false}"},
        {pos: [8, 22, 12], state: "minecraft:oak_leaves{distance:5,persistent:false,waterlogged:false}"},
        {pos: [8, 22, 13], state: "minecraft:oak_leaves{distance:6,persistent:false,waterlogged:false}"},
        {pos: [4, 23, 5], state: "minecraft:oak_leaves{distance:6,persistent:false,waterlogged:false}"},
        {pos: [4, 23, 6], state: "minecraft:oak_leaves{distance:5,persistent:false,waterlogged:false}"},
        {pos: [4, 23, 7], state: "minecraft:oak_leaves{distance:4,persistent:false,waterlogged:false}"},
        {pos: [4, 23, 8], state: "minecraft:oak_leaves{distance:5,persistent:false,waterlogged:false}"},
        {pos: [5, 23, 4], state: "minecraft:oak_leaves{distance:6,persistent:false,waterlogged:false}"},
        {pos: [5, 23, 5], state: "minecraft:oak_leaves{distance:5,persistent:false,waterlogged:false}"},
        {pos: [5, 23, 6], state: "minecraft:oak_leaves{distance:4,persistent:false,waterlogged:false}"},
        {pos: [5, 23, 7], state: "minecraft:oak_leaves{distance:3,persistent:false,waterlogged:false}"},
        {pos: [5, 23, 8], state: "minecraft:oak_leaves{distance:4,persistent:false,waterlogged:false}"},
        {pos: [5, 23, 9], state: "minecraft:oak_leaves{distance:5,persistent:false,waterlogged:false}"},
        {pos: [5, 23, 12], state: "minecraft:oak_leaves{distance:5,persistent:false,waterlogged:false}"},
        {pos: [6, 23, 4], state: "minecraft:oak_leaves{distance:5,persistent:false,waterlogged:false}"},
        {pos: [6, 23, 5], state: "minecraft:oak_leaves{distance:4,persistent:false,waterlogged:false}"},
        {pos: [6, 23, 6], state: "minecraft:oak_leaves{distance:3,persistent:false,waterlogged:false}"},
        {pos: [6, 23, 7], state: "minecraft:oak_leaves{distance:2,persistent:false,waterlogged:false}"},
        {pos: [6, 23, 8], state: "minecraft:oak_leaves{distance:3,persistent:false,waterlogged:false}"},
        {pos: [6, 23, 9], state: "minecraft:oak_leaves{distance:4,persistent:false,waterlogged:false}"},
        {pos: [6, 23, 11], state: "minecraft:oak_leaves{distance:4,persistent:false,waterlogged:false}"},
        {pos: [6, 23, 12], state: "minecraft:oak_leaves{distance:4,persistent:false,waterlogged:false}"},
        {pos: [6, 23, 13], state: "minecraft:oak_leaves{distance:5,persistent:false,waterlogged:false}"},
        {pos: [7, 23, 4], state: "minecraft:oak_leaves{distance:6,persistent:false,waterlogged:false}"},
        {pos: [7, 23, 5], state: "minecraft:oak_leaves{distance:5,persistent:false,waterlogged:false}"},
        {pos: [7, 23, 6], state: "minecraft:oak_leaves{distance:4,persistent:false,waterlogged:false}"},
        {pos: [7, 23, 7], state: "minecraft:oak_leaves{distance:3,persistent:false,waterlogged:false}"},
        {pos: [7, 23, 8], state: "minecraft:oak_leaves{distance:4,persistent:false,waterlogged:false}"},
        {pos: [7, 23, 9], state: "minecraft:oak_leaves{distance:5,persistent:false,waterlogged:false}"},
        {pos: [7, 23, 12], state: "minecraft:oak_leaves{distance:5,persistent:false,waterlogged:false}"},
        {pos: [8, 23, 5], state: "minecraft:oak_leaves{distance:6,persistent:false,waterlogged:false}"},
        {pos: [8, 23, 6], state: "minecraft:oak_leaves{distance:5,persistent:false,waterlogged:false}"},
        {pos: [8, 23, 7], state: "minecraft:oak_leaves{distance:4,persistent:false,waterlogged:false}"},
        {pos: [8, 23, 8], state: "minecraft:oak_leaves{distance:5,persistent:false,waterlogged:false}"},
        {pos: [4, 24, 6], state: "minecraft:oak_leaves{distance:6,persistent:false,waterlogged:false}"},
        {pos: [4, 24, 7], state: "minecraft:oak_leaves{distance:5,persistent:false,waterlogged:false}"},
        {pos: [4, 24, 8], state: "minecraft:oak_leaves{distance:6,persistent:false,waterlogged:false}"},
        {pos: [5, 24, 5], state: "minecraft:oak_leaves{distance:6,persistent:false,waterlogged:false}"},
        {pos: [5, 24, 6], state: "minecraft:oak_leaves{distance:5,persistent:false,waterlogged:false}"},
        {pos: [5, 24, 7], state: "minecraft:oak_leaves{distance:4,persistent:false,waterlogged:false}"},
        {pos: [5, 24, 8], state: "minecraft:oak_leaves{distance:5,persistent:false,waterlogged:false}"},
        {pos: [5, 24, 9], state: "minecraft:oak_leaves{distance:6,persistent:false,waterlogged:false}"},
        {pos: [6, 24, 5], state: "minecraft:oak_leaves{distance:5,persistent:false,waterlogged:false}"},
        {pos: [6, 24, 6], state: "minecraft:oak_leaves{distance:4,persistent:false,waterlogged:false}"},
        {pos: [6, 24, 7], state: "minecraft:oak_leaves{distance:3,persistent:false,waterlogged:false}"},
        {pos: [6, 24, 8], state: "minecraft:oak_leaves{distance:4,persistent:false,waterlogged:false}"},
        {pos: [6, 24, 9], state: "minecraft:oak_leaves{distance:5,persistent:false,waterlogged:false}"},
        {pos: [7, 24, 5], state: "minecraft:oak_leaves{distance:6,persistent:false,waterlogged:false}"},
        {pos: [7, 24, 6], state: "minecraft:oak_leaves{distance:5,persistent:false,waterlogged:false}"},
        {pos: [7, 24, 7], state: "minecraft:oak_leaves{distance:4,persistent:false,waterlogged:false}"},
        {pos: [7, 24, 8], state: "minecraft:oak_leaves{distance:5,persistent:false,waterlogged:false}"},
        {pos: [7, 24, 9], state: "minecraft:oak_leaves{distance:6,persistent:false,waterlogged:false}"},
        {pos: [8, 24, 6], state: "minecraft:oak_leaves{distance:6,persistent:false,waterlogged:false}"},
        {pos: [8, 24, 7], state: "minecraft:oak_leaves{distance:5,persistent:false,waterlogged:false}"},
        {pos: [8, 24, 8], state: "minecraft:oak_leaves{distance:6,persistent:false,waterlogged:false}"},
        {pos: [5, 25, 7], state: "minecraft:oak_leaves{distance:5,persistent:false,waterlogged:false}"},
        {pos: [6, 25, 6], state: "minecraft:oak_leaves{distance:5,persistent:false,waterlogged:false}"},
        {pos: [6, 25, 7], state: "minecraft:oak_leaves{distance:4,persistent:false,waterlogged:false}"},
        {pos: [6, 25, 8], state: "minecraft:oak_leaves{distance:5,persistent:false,waterlogged:false}"},
        {pos: [7, 25, 7], state: "minecraft:oak_leaves{distance:5,persistent:false,waterlogged:false}"}
    ],
    entities: [
        {blockPos: [2, 11, 5], pos: [2.6874205906387942d, 11.0d, 5.271294940410371d], nbt: {AbsorptionAmount: 0.0f, Age: 0, Air: 300s, ArmorDropChances: [0.085f, 0.085f, 0.085f, 0.085f], ArmorItems: [{}, {}, {}, {}], Attributes: [{Base: 0.23000000417232513d, Name: "minecraft:generic.movement_speed"}, {Base: 0.0d, Name: "forge:step_height_addition"}, {Base: 0.08d, Name: "forge:entity_gravity"}], BalmData: {}, Brain: {memories: {}}, CanPickUpLoot: 0b, CanUpdate: 1b, Color: 0b, DeathTime: 0s, FallDistance: 0.0f, FallFlying: 0b, Fire: -1s, ForcedAge: 0, ForgeCaps: {"curios:inventory": {Curios: []}}, ForgeData: {}, HandDropChances: [0.085f, 0.085f], HandItems: [{}, {}], Health: 8.0f, HurtByTimestamp: 0, HurtTime: 0s, InLove: 0, Invulnerable: 0b, LeftHanded: 0b, Motion: [0.0d, -0.0784000015258789d, 0.0d], OnGround: 1b, PersistenceRequired: 0b, PortalCooldown: 0, Pos: [8194.687420590639d, 64.0d, 8197.27129494041d], Rotation: [272.18256f, 0.0f], Sheared: 0b, UUID: [I; 2051093414, 2109687947, -1998461288, -383554022], id: "minecraft:sheep"}},
        {blockPos: [1, 12, 8], pos: [1.03125d, 12.5d, 8.5d], nbt: {Air: 300s, BalmData: {}, CanUpdate: 1b, Facing: 5b, FallDistance: 0.0f, Fire: -1s, Fixed: 0b, ForgeData: {}, Invisible: 0b, Invulnerable: 0b, Item: {Count: 1b, id: "minecraft:writable_book", tag: {pages: ["Resources on Potato Island are limited. Do not throw anything away! If you are careful and think about what you are doing, there are enough resources to get you up and going.

Good Luck and Have Fun!

CM"]}}, ItemDropChance: 1.0f, ItemRotation: 0b, Motion: [0.0d, 0.0d, 0.0d], OnGround: 0b, PortalCooldown: 0, Pos: [8193.03125d, 65.5d, 8200.5d], Rotation: [-450.0f, 0.0f], TileX: 8193, TileY: 65, TileZ: 8200, UUID: [I; -665407, 1740196351, -2044778435, -271953422], id: "minecraft:glow_item_frame"}},
        {blockPos: [1, 13, 10], pos: [1.3265184620195214d, 13.723688590808592d, 10.71596945823876d], nbt: {AbsorptionAmount: 0.0f, Age: 0, Air: 300s, AngerTime: 0, ArmorDropChances: [0.085f, 0.085f, 0.085f, 0.085f], ArmorItems: [{}, {}, {}, {}], Attributes: [{Base: 0.30000001192092896d, Name: "minecraft:generic.movement_speed"}, {Base: 0.0d, Name: "forge:step_height_addition"}, {Base: 0.08d, Name: "forge:entity_gravity"}], BalmData: {}, Brain: {memories: {}}, CanPickUpLoot: 0b, CanUpdate: 1b, CannotEnterHiveTicks: 0, CropsGrownSincePollination: 0, DeathTime: 0s, FallDistance: 0.0f, FallFlying: 0b, Fire: -1s, FlowerPos: {X: 8193, Y: 66, Z: 8202}, ForcedAge: 0, ForgeCaps: {"curios:inventory": {Curios: []}}, ForgeData: {}, HandDropChances: [0.085f, 0.085f], HandItems: [{}, {}], HasNectar: 0b, HasStung: 0b, Health: 10.0f, HivePos: {X: 8199, Y: 67, Z: 8199}, HurtByTimestamp: 0, HurtTime: 0s, InLove: 0, Invulnerable: 0b, LeftHanded: 0b, Motion: [-0.02038340086582895d, 0.01712039170351353d, 0.0020066205119020184d], NoGravity: 1b, OnGround: 0b, PersistenceRequired: 0b, PortalCooldown: 0, Pos: [8193.32651846202d, 66.72368859080859d, 8202.715969458239d], Rotation: [167.16743f, 57.20279f], TicksSincePollination: 306, UUID: [I; 415479736, -221624677, -1105896214, 1060057429], id: "minecraft:bee"}}
    ],
    palette: [
        "minecraft:stone",
        "create:zinc_ore",
        "minecraft:gravel",
        "minecraft:iron_ore",
        "minecraft:coal_ore",
        "minecraft:andesite",
        "minecraft:diorite",
        "minecraft:dirt",
        "minecraft:dripstone_block",
        "minecraft:clay",
        "minecraft:sand",
        "minecraft:grass_block{snowy:false}",
        "minecraft:oak_log{axis:y}",
        "minecraft:oak_leaves{distance:1,persistent:false,waterlogged:false}",
        "minecraft:oak_log{axis:z}",
        "minecraft:oak_log{axis:x}",
        "minecraft:oak_leaves{distance:2,persistent:false,waterlogged:false}",
        "minecraft:oak_leaves{distance:3,persistent:false,waterlogged:false}",
        "minecraft:oak_leaves{distance:4,persistent:false,waterlogged:false}",
        "minecraft:oak_leaves{distance:5,persistent:false,waterlogged:false}",
        "minecraft:oak_leaves{distance:6,persistent:false,waterlogged:false}",
        "minecraft:water{level:8}",
        "minecraft:vine{east:true,north:false,south:false,up:false,west:false}",
        "minecraft:vine{east:false,north:false,south:false,up:false,west:true}",
        "minecraft:vine{east:false,north:true,south:false,up:false,west:false}",
        "minecraft:vine{east:false,north:false,south:true,up:false,west:false}",
        "minecraft:cobweb",
        "minecraft:pointed_dripstone{thickness:tip,vertical_direction:down,waterlogged:false}",
        "minecraft:vine{east:true,north:true,south:false,up:true,west:false}",
        "minecraft:lava{level:0}",
        "minecraft:vine{east:false,north:false,south:false,up:true,west:false}",
        "minecraft:pointed_dripstone{thickness:frustum,vertical_direction:down,waterlogged:false}",
        "minecraft:vine{east:false,north:false,south:true,up:true,west:false}",
        "minecraft:vine{east:false,north:false,south:false,up:true,west:true}",
        "minecraft:vine{east:true,north:false,south:true,up:false,west:false}",
        "minecraft:water{level:1}",
        "minecraft:water{level:0}",
        "minecraft:vine{east:true,north:false,south:true,up:true,west:false}",
        "minecraft:tall_grass{half:lower}",
        "minecraft:farmland{moisture:7}",
        "minecraft:grass",
        "minecraft:tall_grass{half:upper}",
        "minecraft:torch",
        "minecraft:poppy",
        "minecraft:potatoes{age:7}",
        "minecraft:dandelion",
        "minecraft:cornflower",
        "minecraft:dark_oak_sign{rotation:12,waterlogged:false}",
        "minecraft:bee_nest{facing:south,honey_level:5}"
    ],
    Railways_DataVersion: 2
}